version: '3.3'

services:

  pygeoapi_test:
    
    image: geopython/pygeoapi_test:latest

    container_name: pygeoapi_test

    expose:
      - "80"

#    ports:
#     - "5000:80"

    environment:
     - SCRIPT_NAME=/pygeoapi_test

    labels:
      - "traefik.enable=true"
      # local http router
      - "traefik.http.routers.pygeoapi_test_lhttp.rule=Host(`local.map5.nl`) || Host(`localhost`) && PathPrefix(`/pygeoapi_test`)"
      - "traefik.http.routers.pygeoapi_test_lhttp.entrypoints=http"
      - "traefik.http.routers.pygeoapi_test_lhttp.middlewares=secure-headers@file"
      # https router
      - "traefik.http.routers.pygeoapi_test_https.rule=Host(`oapi.map5.nl`) && PathPrefix(`/pygeoapi_test`)"
      - "traefik.http.routers.pygeoapi_test_https.entrypoints=https"
      - "traefik.http.routers.pygeoapi_test_https.tls=true"
      - "traefik.http.routers.pygeoapi_test_https.tls.certresolver=le"
      - "traefik.http.routers.pygeoapi_test_https.tls.options=my_default@file"
      - "traefik.http.routers.pygeoapi_test_https.middlewares=secure-headers@file"

      - "traefik.frontend.priority=100"
      - "traefik.docker.network=service-network"

networks:
  default:
    external:
      name: service-network
